Workbook

Sheet 00_HUONG_DAN
A1: MẪU NHẬP KỊCH BẢN GAME TƯƠNG TÁC
A2: Workbook chuẩn hóa cấu trúc từ 15-movie-template.ts. Team tài liệu nhập ô màu vàng; team dev dùng các bảng dữ liệu đã chuẩn hóa để dựng mảng script JSON/TypeScript và upsert movie.
A4: 1. QUY TRÌNH SỬ DỤNG
A5: Bước | B5: Người thực hiện | C5: Thao tác | D5: Kết quả cần đạt | E5: Không được làm
A6: 1 | B6: Team tài liệu | C6: Điền 01_THONG_TIN_Game | D6: Đủ mã chương, mục, tiêu đề và thông tin seed | E6: Không đổi tên trường kỹ thuật
A7: 2 | B7: Team tài liệu | C7: Điền 02_KICH_BAN_NODES theo NodeOrder | D7: Mỗi dòng là 1 scene/say/choice/act/end | E7: Không gộp nhiều node trong một dòng
A8: 3 | B8: Team tài liệu | C8: Điền 03_LUA_CHON theo ChoiceNodeId | D8: Mỗi choice có 2–4 phương án và đúng quy tắc ChoiceMode | E8: Không bỏ phản hồi phương án
A9: 4 | B9: Reviewer | C9: Kiểm tra 05_KIEM_TRA_QA | D9: Không còn lỗi cấu trúc; checklist chuyên môn đạt | E9: Không bàn giao khi còn CẦN SỬA
A10: 5 | B10: Team dev | C10: Chuyển đổi theo 06_DEV_MAPPING | D10: Seed chạy được và upsert theo muc | E10: Không tự thay đổi nội dung chuyên môn
A12: 2. QUY ƯỚC MÀU VÀ TRẠNG THÁI
A13: Màu/Trạng thái | B13: Ý nghĩa | C13: Hành động
A14: Ô màu vàng | B14: Dữ liệu team tài liệu được phép nhập/sửa | C14: Điền nội dung, không xóa tiêu đề cột
A15: Ô màu xám | B15: Công thức hoặc thông tin kỹ thuật | C15: Không sửa
A16: HỢP LỆ | B16: Dòng đạt kiểm tra cấu trúc cơ bản | C16: Chuyển sang review chuyên môn
A17: CẦN SỬA | B17: Thiếu dữ liệu, sai liên kết hoặc sai quy tắc | C17: Đọc cột Lỗi cấu trúc và chỉnh lại
A19: 3. QUY TẮC NỘI DUNG BẮT BUỘC
A20: Nhóm | B20: Quy tắc | C20: Mức độ | D20: Lý do
A21: Cấu trúc game | B21: Thông thường 2–4 màn; mỗi màn bắt đầu bằng scene, kết thúc bằng act; toàn game có đúng 1 end. | C21: Bắt buộc | D21: Khớp ScriptNode trong template.
A22: Choice kiến thức | B22: ChoiceMode = Kiến thức: 2–4 phương án và đúng 1 IsCorrect = Có. | C22: Bắt buộc | D22: Dùng để kiểm tra và chấm đúng/sai.
A23: Choice tương tác | B23: ChoiceMode = Tương tác: 2–4 phương án và không đánh dấu đáp án đúng; có thể dùng dc. | C23: Bắt buộc | D23: Khớp các lựa chọn thái độ/thiện cảm trong kịch bản mẫu.
A24: Phản hồi | B24: Mọi phương án phải có ReplyText; phương án sai của câu kiến thức phải giải thích vì sao sai. | C24: Bắt buộc | D24: Bảo đảm giá trị học tập.
A25: Nhân vật | B25: Chỉ dùng SpeakerKey trong danh mục; nhân vật mới phải được dev bổ sung vào CHARACTERS. | C25: Bắt buộc | D25: Tránh key không tồn tại.
A26: Cảnh nền | B26: Chỉ dùng Background trong danh mục; cảnh mới cần asset/SVG được dev xác nhận. | C26: Bắt buộc | D26: Tránh thiếu tài nguyên giao diện.
A27: Văn bản | B27: Không dùng HTML; câu hỏi không đánh đố; lời thoại tự nhiên, phù hợp vai trò. | C27: Khuyến nghị cao | D27: Theo nguyên tắc biên soạn của template.
A28: Thứ tự | B28: NodeOrder và NodeId phải duy nhất; option sắp xếp bằng OptionOrder. | C28: Bắt buộc | D28: Bảo toàn thứ tự mảng script/opts.
A30: 4. TRƯỜNG HỢP ĐẶC BIỆT
A31: Tình huống | B31: Cách xử lý
A32: Lời dẫn chuyện | B32: NodeType = say, SpeakerKey = narr, Mood để trống.
A33: Choice mở đầu kiểu “Bạn sẵn sàng chứ?” | B33: Chọn ChoiceMode = Tương tác; IsCorrect của mọi option = Không; dùng dc nếu cần.
A34: Thêm nhân vật/cảnh nền | B34: Bổ sung tại 04_DANH_MUC, ghi rõ cần dev bổ sung và chỉ dùng sau khi được duyệt.
A35: Điểm thiện cảm dc | B35: Nhập số nguyên dương/âm khi cần; để trống để dùng cơ chế mặc định.
A37: Thông tin mẫu | B37: Giá trị
A38: Nguồn cấu trúc | B38: 15-movie-template.ts
A39: Phiên bản workbook | B39: 1.1.0 — 2026-07-10

Sheet 01_THONG_TIN_PHIM
A1: 01 — THÔNG TIN game / THÔNG SỐ SEED
A2: Điền cột Giá trị. Trường có Bắt buộc = Có phải hoàn thành trước khi bàn giao.
A4: Trường kỹ thuật | B4: Bắt buộc | C4: Giá trị | D4: Ví dụ | E4: Quy tắc / Ghi chú
A5: chapterCode | B5: Có | C5: 6 | D5: 2 | E5: Phải tồn tại trong bảng chapter trước khi seed.
A6: muc | B6: Có | C6: 6.2 | D6: 2.1 | E6: Khóa nghiệp vụ dùng tìm movie hiện có để update/create.
A7: movieTitle | B7: Có | C7: Game tương tác: Hội nhập kinh tế quốc tế của Việt Nam | D7: game tương tác: Hàng hóa và tiền tệ | E7: Tên hiển thị của game.
A8: seedFunctionName | B8: Có | C8: seedMovieChuong6Muc62 | D8: seedMovieChuong2 | E8: camelCase, không dấu, duy nhất.
A9: outputFileName | B9: Có | C9: 19-movie-chuong-6-muc-6-2.ts | D9: 16-movie-chuong-2.ts | E9: Tên file TypeScript sau chuyển đổi.
A10: seedLogLabel | B10: Có | C10: Interactive Movies (Chương 6 - Mục 6.2) | D10: Interactive Movies (Chương 2) | E10: Nhãn dùng trong seedLog().
A11: author | B11: Có | C11: Lê Ngọc | D11: Nguyễn Văn A | E11: Người biên soạn.
A12: reviewer | B12: Có | C12: Lê Đặng Nhật Huy | D12: Trần Thị B | E12: Người duyệt nội dung.
A13: version | B13: Có | C13: 1.0 | D13: 1.1 | E13: Tăng version khi chỉnh sau bàn giao.
A14: documentStatus | B14: Có | C14: Đang soạn | D14: Đã duyệt | E14: Chỉ bàn giao khi Đã duyệt.
A15: sourceReference | B15: Không | C15: Giáo trình Kinh tế chính trị Mác - Lênin, Chương 6, Mục 6.2, trang gốc 162–179. | D15: Giáo trình Chương 2, trang 30–45 | E15: Nguồn chuyên môn.
A16: changeSummary | B16: Không | C16: Bao phủ khái niệm, tính tất yếu, tác động và phương hướng nâng cao hiệu quả hội nhập. | D16: Tạo mới kịch bản Chương 2 | E16: Tóm tắt thay đổi.
A18: KIỂM TRA NHANH
A19: Chỉ số | B19: Giá trị | C19: Trạng thái
A20: Trường bắt buộc còn trống | B20: =COUNTBLANK(C5:C14) -> 0 | C20: =IF(B20=0,"HỢP LỆ","CẦN SỬA") -> HỢP LỆ
A21: Trạng thái tài liệu | B21: =C14 -> Đang soạn | C21: =IF(B21="Đã duyệt","HỢP LỆ","CHƯA DUYỆT") -> CHƯA DUYỆT
A22: Sẵn sàng bàn giao dev | B22: =IF(AND(C20="HỢP LỆ",C21="HỢP LỆ"),"CÓ","KHÔNG") -> KHÔNG | C22: =IF(B22="CÓ","HỢP LỆ","CẦN SỬA") -> CẦN SỬA
A23: Ghi chú | B23: Công thức chỉ kiểm tra cấu trúc; reviewer vẫn phải kiểm tra kiến thức.

Sheet 02_KICH_BAN_NODES
A1: 02 — KỊCH BẢN: DANH SÁCH SCRIPT NODE
A2: Mỗi dòng là một ScriptNode. ChoiceMode chỉ dùng để QA/biên soạn và không cần ghi vào object TypeScript.
A4: NodeOrder* | B4: NodeId* | C4: ActNo | D4: NodeType* | E4: ChoiceMode | F4: Background | G4: SceneName | H4: SpeakerKey | I4: Mood | J4: Text / Question | K4: ActRoman | L4: Ghi chú biên soạn | M4: Trạng thái | N4: Lỗi cấu trúc
A5: 1 | B5: N001 | C5: 1 | D5: scene | F5: thukho | G5: Màn I · Bản chất và cấp độ hội nhập | L5: Bắt đầu màn 1 | M5: =IF(A5="","",IF(N5="","HỢP LỆ","CẦN SỬA")) -> HỢP LỆ | N5: =IF(A5="","",IF(B5="","Thiếu NodeId",IF(D5="","Thiếu NodeType",IF(COUNTIF($B$5:$B$204,B5)>1,"NodeId bị trùng",IF(COUNTIF($A$5:$A$204,A5)>1,"NodeOrder bị trùng",IF(AND(D5="scene",OR(C5="",F5="",G5="")),"scene cần ActNo, Background, SceneName",IF(AND(D5="say",OR(H5="",J5="")),"say cần SpeakerKey và Text",IF(AND(D5="choice",OR(E5="",H5="",I5="",J5="")),"choice cần ChoiceMode, SpeakerKey, Mood, Question",IF(AND(D5="act",K5=""),"act cần số La Mã",IF(AND(D5="end",COUNTIF($D$5:$D$204,"end")<>1),"Phải có đúng 1 node end",""))))))))))
A6: 2 | B6: N002 | C6: 1 | D6: say | H6: narr | J6: Bản đồ thương mại toàn cầu xuất hiện với các tuyến hàng hóa, vốn, công nghệ, dịch vụ và lao động kết nối Việt Nam với nhiều quốc gia và tổ chức kinh tế. | M6: =IF(A6="","",IF(N6="","HỢP LỆ","CẦN SỬA")) -> HỢP LỆ | N6: =IF(A6="","",IF(B6="","Thiếu NodeId",IF(D6="","Thiếu NodeType",IF(COUNTIF($B$5:$B$204,B6)>1,"NodeId bị trùng",IF(COUNTIF($A$5:$A$204,A6)>1,"NodeOrder bị trùng",IF(AND(D6="scene",OR(C6="",F6="",G6="")),"scene cần ActNo, Background, SceneName",IF(AND(D6="say",OR(H6="",J6="")),"say cần SpeakerKey và Text",IF(AND(D6="choice",OR(E6="",H6="",I6="",J6="")),"choice cần ChoiceMode, SpeakerKey, Mood, Question",IF(AND(D6="act",K6=""),"act cần số La Mã",IF(AND(D6="end",COUNTIF($D$5:$D$204,"end")<>1),"Phải có đúng 1 node end",""))))))))))
A7: 3 | B7: N003 | C7: 1 | D7: say | H7: lam | I7: neutral | J7: Hội nhập là quá trình gắn kết nền kinh tế quốc gia với khu vực và thế giới trên cơ sở lợi ích, chuẩn mực và cam kết. | M7: =IF(A7="","",IF(N7="","HỢP LỆ","CẦN SỬA")) -> HỢP LỆ | N7: =IF(A7="","",IF(B7="","Thiếu NodeId",IF(D7="","Thiếu NodeType",IF(COUNTIF($B$5:$B$204,B7)>1,"NodeId bị trùng",IF(COUNTIF($A$5:$A$204,A7)>1,"NodeOrder bị trùng",IF(AND(D7="scene",OR(C7="",F7="",G7="")),"scene cần ActNo, Background, SceneName",IF(AND(D7="say",OR(H7="",J7="")),"say cần SpeakerKey và Text",IF(AND(D7="choice",OR(E7="",H7="",I7="",J7="")),"choice cần ChoiceMode, SpeakerKey, Mood, Question",IF(AND(D7="act",K7=""),"act cần số La Mã",IF(AND(D7="end",COUNTIF($D$5:$D$204,"end")<>1),"Phải có đúng 1 node end",""))))))))))
A8: 4 | B8: N004 | C8: 1 | D8: choice | E8: Tương tác | H8: lam | I8: neutral | J8: Bạn muốn mở tuyến kết nối nào trước? | L8: Nhập option ở sheet 03 | M8: =IF(A8="","",IF(N8="","HỢP LỆ","CẦN SỬA")) -> HỢP LỆ | N8: =IF(A8="","",IF(B8="","Thiếu NodeId",IF(D8="","Thiếu NodeType",IF(COUNTIF($B$5:$B$204,B8)>1,"NodeId bị trùng",IF(COUNTIF($A$5:$A$204,A8)>1,"NodeOrder bị trùng",IF(AND(D8="scene",OR(C8="",F8="",G8="")),"scene cần ActNo, Background, SceneName",IF(AND(D8="say",OR(H8="",J8="")),"say cần SpeakerKey và Text",IF(AND(D8="choice",OR(E8="",H8="",I8="",J8="")),"choice cần ChoiceMode, SpeakerKey, Mood, Question",IF(AND(D8="act",K8=""),"act cần số La Mã",IF(AND(D8="end",COUNTIF($D$5:$D$204,"end")<>1),"Phải có đúng 1 node end",""))))))))))
A9: 5 | B9: N005 | C9: 1 | D9: choice | E9: Kiến thức | H9: an | I9: neutral | J9: Hội nhập kinh tế quốc tế của một quốc gia là gì? | L9: Nhập option ở sheet 03 | M9: =IF(A9="","",IF(N9="","HỢP LỆ","CẦN SỬA")) -> HỢP LỆ | N9: =IF(A9="","",IF(B9="","Thiếu NodeId",IF(D9="","Thiếu NodeType",IF(COUNTIF($B$5:$B$204,B9)>1,"NodeId bị trùng",IF(COUNTIF($A$5:$A$204,A9)>1,"NodeOrder bị trùng",IF(AND(D9="scene",OR(C9="",F9="",G9="")),"scene cần ActNo, Background, SceneName",IF(AND(D9="say",OR(H9="",J9="")),"say cần SpeakerKey và Text",IF(AND(D9="choice",OR(E9="",H9="",I9="",J9="")),"choice cần ChoiceMode, SpeakerKey, Mood, Question",IF(AND(D9="act",K9=""),"act cần số La Mã",IF(AND(D9="end",COUNTIF($D$5:$D$204,"end")<>1),"Phải có đúng 1 node end",""))))))))))
A10: 6 | B10: N006 | C10: 1 | D10: choice | E10: Kiến thức | H10: lam | I10: neutral | J10: Vì sao hội nhập kinh tế quốc tế trở thành tất yếu khách quan? | L10: Nhập option ở sheet 03 | M10: =IF(A10="","",IF(N10="","HỢP LỆ","CẦN SỬA")) -> HỢP LỆ | N10: =IF(A10="","",IF(B10="","Thiếu NodeId",IF(D10="","Thiếu NodeType",IF(COUNTIF($B$5:$B$204,B10)>1,"NodeId bị trùng",IF(COUNTIF($A$5:$A$204,A10)>1,"NodeOrder bị trùng",IF(AND(D10="scene",OR(C10="",F10="",G10="")),"scene cần ActNo, Background, SceneName",IF(AND(D10="say",OR(H10="",J10="")),"say cần SpeakerKey và Text",IF(AND(D10="choice",OR(E10="",H10="",I10="",J10="")),"choice cần ChoiceMode, SpeakerKey, Mood, Question",IF(AND(D10="act",K10=""),"act cần số La Mã",IF(AND(D10="end",COUNTIF($D$5:$D$204,"end")<>1),"Phải có đúng 1 node end",""))))))))))
A11: 7 | B11: N007 | C11: 1 | D11: choice | E11: Kiến thức | H11: khoa | I11: neutral | J11: Nội dung hội nhập kinh tế quốc tế được thể hiện chủ yếu ở đâu? | L11: Nhập option ở sheet 03 | M11: =IF(A11="","",IF(N11="","HỢP LỆ","CẦN SỬA")) -> HỢP LỆ | N11: =IF(A11="","",IF(B11="","Thiếu NodeId",IF(D11="","Thiếu NodeType",IF(COUNTIF($B$5:$B$204,B11)>1,"NodeId bị trùng",IF(COUNTIF($A$5:$A$204,A11)>1,"NodeOrder bị trùng",IF(AND(D11="scene",OR(C11="",F11="",G11="")),"scene cần ActNo, Background, SceneName",IF(AND(D11="say",OR(H11="",J11="")),"say cần SpeakerKey và Text",IF(AND(D11="choice",OR(E11="",H11="",I11="",J11="")),"choice cần ChoiceMode, SpeakerKey, Mood, Question",IF(AND(D11="act",K11=""),"act cần số La Mã",IF(AND(D11="end",COUNTIF($D$5:$D$204,"end")<>1),"Phải có đúng 1 node end",""))))))))))
A12: 8 | B12: N008 | C12: 1 | D12: choice | E12: Kiến thức | H12: an | I12: neutral | J12: Các hình thức hội nhập kinh tế quốc tế có thể diễn ra như thế nào? | L12: Nhập option ở sheet 03 | M12: =IF(A12="","",IF(N12="","HỢP LỆ","CẦN SỬA")) -> HỢP LỆ | N12: =IF(A12="","",IF(B12="","Thiếu NodeId",IF(D12="","Thiếu NodeType",IF(COUNTIF($B$5:$B$204,B12)>1,"NodeId bị trùng",IF(COUNTIF($A$5:$A$204,A12)>1,"NodeOrder bị trùng",IF(AND(D12="scene",OR(C12="",F12="",G12="")),"scene cần ActNo, Background, SceneName",IF(AND(D12="say",OR(H12="",J12="")),"say cần SpeakerKey và Text",IF(AND(D12="choice",OR(E12="",H12="",I12="",J12="")),"choice cần ChoiceMode, SpeakerKey, Mood, Question",IF(AND(D12="act",K12=""),"act cần số La Mã",IF(AND(D12="end",COUNTIF($D$5:$D$204,"end")<>1),"Phải có đúng 1 node end",""))))))))))
A13: 9 | B13: N009 | C13: 1 | D13: choice | E13: Kiến thức | H13: lam | I13: neutral | J13: Trình tự nào phản ánh các mức độ hội nhập kinh tế khu vực từ thấp đến cao? | L13: Nhập option ở sheet 03 | M13: =IF(A13="","",IF(N13="","HỢP LỆ","CẦN SỬA")) -> HỢP LỆ | N13: =IF(A13="","",IF(B13="","Thiếu NodeId",IF(D13="","Thiếu NodeType",IF(COUNTIF($B$5:$B$204,B13)>1,"NodeId bị trùng",IF(COUNTIF($A$5:$A$204,A13)>1,"NodeOrder bị trùng",IF(AND(D13="scene",OR(C13="",F13="",G13="")),"scene cần ActNo, Background, SceneName",IF(AND(D13="say",OR(H13="",J13="")),"say cần SpeakerKey và Text",IF(AND(D13="choice",OR(E13="",H13="",I13="",J13="")),"choice cần ChoiceMode, SpeakerKey, Mood, Question",IF(AND(D13="act",K13=""),"act cần số La Mã",IF(AND(D13="end",COUNTIF($D$5:$D$204,"end")<>1),"Phải có đúng 1 node end",""))))))))))
A14: 10 | B14: N010 | C14: 1 | D14: choice | E14: Kiến thức | H14: khoa | I14: neutral | J14: Hội nhập có đồng nghĩa với hòa tan và từ bỏ lợi ích quốc gia không? | L14: Nhập option ở sheet 03 | M14: =IF(A14="","",IF(N14="","HỢP LỆ","CẦN SỬA")) -> HỢP LỆ | N14: =IF(A14="","",IF(B14="","Thiếu NodeId",IF(D14="","Thiếu NodeType",IF(COUNTIF($B$5:$B$204,B14)>1,"NodeId bị trùng",IF(COUNTIF($A$5:$A$204,A14)>1,"NodeOrder bị trùng",IF(AND(D14="scene",OR(C14="",F14="",G14="")),"scene cần ActNo, Background, SceneName",IF(AND(D14="say",OR(H14="",J14="")),"say cần SpeakerKey và Text",IF(AND(D14="choice",OR(E14="",H14="",I14="",J14="")),"choice cần ChoiceMode, SpeakerKey, Mood, Question",IF(AND(D14="act",K14=""),"act cần số La Mã",IF(AND(D14="end",COUNTIF($D$5:$D$204,"end")<>1),"Phải có đúng 1 node end",""))))))))))
A15: 11 | B15: N011 | C15: 1 | D15: act | K15: I | L15: Kết thúc màn I | M15: =IF(A15="","",IF(N15="","HỢP LỆ","CẦN SỬA")) -> HỢP LỆ | N15: =IF(A15="","",IF(B15="","Thiếu NodeId",IF(D15="","Thiếu NodeType",IF(COUNTIF($B$5:$B$204,B15)>1,"NodeId bị trùng",IF(COUNTIF($A$5:$A$204,A15)>1,"NodeOrder bị trùng",IF(AND(D15="scene",OR(C15="",F15="",G15="")),"scene cần ActNo, Background, SceneName",IF(AND(D15="say",OR(H15="",J15="")),"say cần SpeakerKey và Text",IF(AND(D15="choice",OR(E15="",H15="",I15="",J15="")),"choice cần ChoiceMode, SpeakerKey, Mood, Question",IF(AND(D15="act",K15=""),"act cần số La Mã",IF(AND(D15="end",COUNTIF($D$5:$D$204,"end")<>1),"Phải có đúng 1 node end",""))))))))))
A16: 12 | B16: N012 | C16: 2 | D16: scene | F16: hoithao | G16: Màn II · Tác động hai mặt của hội nhập | L16: Bắt đầu màn 2 | M16: =IF(A16="","",IF(N16="","HỢP LỆ","CẦN SỬA")) -> HỢP LỆ | N16: =IF(A16="","",IF(B16="","Thiếu NodeId",IF(D16="","Thiếu NodeType",IF(COUNTIF($B$5:$B$204,B16)>1,"NodeId bị trùng",IF(COUNTIF($A$5:$A$204,A16)>1,"NodeOrder bị trùng",IF(AND(D16="scene",OR(C16="",F16="",G16="")),"scene cần ActNo, Background, SceneName",IF(AND(D16="say",OR(H16="",J16="")),"say cần SpeakerKey và Text",IF(AND(D16="choice",OR(E16="",H16="",I16="",J16="")),"choice cần ChoiceMode, SpeakerKey, Mood, Question",IF(AND(D16="act",K16=""),"act cần số La Mã",IF(AND(D16="end",COUNTIF($D$5:$D$204,"end")<>1),"Phải có đúng 1 node end",""))))))))))
A17: 13 | B17: N013 | C17: 2 | D17: say | H17: narr | J17: Hai màn hình hiển thị những kết quả khác nhau: một bên là thị trường, vốn và công nghệ; bên kia là cạnh tranh gay gắt, phụ thuộc và những cú sốc từ bên ngoài. | M17: =IF(A17="","",IF(N17="","HỢP LỆ","CẦN SỬA")) -> HỢP LỆ | N17: =IF(A17="","",IF(B17="","Thiếu NodeId",IF(D17="","Thiếu NodeType",IF(COUNTIF($B$5:$B$204,B17)>1,"NodeId bị trùng",IF(COUNTIF($A$5:$A$204,A17)>1,"NodeOrder bị trùng",IF(AND(D17="scene",OR(C17="",F17="",G17="")),"scene cần ActNo, Background, SceneName",IF(AND(D17="say",OR(H17="",J17="")),"say cần SpeakerKey và Text",IF(AND(D17="choice",OR(E17="",H17="",I17="",J17="")),"choice cần ChoiceMode, SpeakerKey, Mood, Question",IF(AND(D17="act",K17=""),"act cần số La Mã",IF(AND(D17="end",COUNTIF($D$5:$D$204,"end")<>1),"Phải có đúng 1 node end",""))))))))))
A18: 14 | B18: N014 | C18: 2 | D18: say | H18: khoa | I18: stern | J18: Đánh giá hội nhập phải nhìn đầy đủ hai mặt; cơ hội có thể thành thách thức nếu năng lực cạnh tranh và thể chế yếu. | M18: =IF(A18="","",IF(N18="","HỢP LỆ","CẦN SỬA")) -> HỢP LỆ | N18: =IF(A18="","",IF(B18="","Thiếu NodeId",IF(D18="","Thiếu NodeType",IF(COUNTIF($B$5:$B$204,B18)>1,"NodeId bị trùng",IF(COUNTIF($A$5:$A$204,A18)>1,"NodeOrder bị trùng",IF(AND(D18="scene",OR(C18="",F18="",G18="")),"scene cần ActNo, Background, SceneName",IF(AND(D18="say",OR(H18="",J18="")),"say cần SpeakerKey và Text",IF(AND(D18="choice",OR(E18="",H18="",I18="",J18="")),"choice cần ChoiceMode, SpeakerKey, Mood, Question",IF(AND(D18="act",K18=""),"act cần số La Mã",IF(AND(D18="end",COUNTIF($D$5:$D$204,"end")<>1),"Phải có đúng 1 node end",""))))))))))
A19: 15 | B19: N015 | C19: 2 | D19: choice | E19: Kiến thức | H19: khoa | I19: neutral | J19: Tác động tích cực nổi bật của hội nhập đối với tăng trưởng là gì? | L19: Nhập option ở sheet 03 | M19: =IF(A19="","",IF(N19="","HỢP LỆ","CẦN SỬA")) -> HỢP LỆ | N19: =IF(A19="","",IF(B19="","Thiếu NodeId",IF(D19="","Thiếu NodeType",IF(COUNTIF($B$5:$B$204,B19)>1,"NodeId bị trùng",IF(COUNTIF($A$5:$A$204,A19)>1,"NodeOrder bị trùng",IF(AND(D19="scene",OR(C19="",F19="",G19="")),"scene cần ActNo, Background, SceneName",IF(AND(D19="say",OR(H19="",J19="")),"say cần SpeakerKey và Text",IF(AND(D19="choice",OR(E19="",H19="",I19="",J19="")),"choice cần ChoiceMode, SpeakerKey, Mood, Question",IF(AND(D19="act",K19=""),"act cần số La Mã",IF(AND(D19="end",COUNTIF($D$5:$D$204,"end")<>1),"Phải có đúng 1 node end",""))))))))))
A20: 16 | B20: N016 | C20: 2 | D20: choice | E20: Kiến thức | H20: lam | I20: neutral | J20: Hội nhập tác động như thế nào đến thể chế và năng lực cạnh tranh? | L20: Nhập option ở sheet 03 | M20: =IF(A20="","",IF(N20="","HỢP LỆ","CẦN SỬA")) -> HỢP LỆ | N20: =IF(A20="","",IF(B20="","Thiếu NodeId",IF(D20="","Thiếu NodeType",IF(COUNTIF($B$5:$B$204,B20)>1,"NodeId bị trùng",IF(COUNTIF($A$5:$A$204,A20)>1,"NodeOrder bị trùng",IF(AND(D20="scene",OR(C20="",F20="",G20="")),"scene cần ActNo, Background, SceneName",IF(AND(D20="say",OR(H20="",J20="")),"say cần SpeakerKey và Text",IF(AND(D20="choice",OR(E20="",H20="",I20="",J20="")),"choice cần ChoiceMode, SpeakerKey, Mood, Question",IF(AND(D20="act",K20=""),"act cần số La Mã",IF(AND(D20="end",COUNTIF($D$5:$D$204,"end")<>1),"Phải có đúng 1 node end",""))))))))))
A21: 17 | B21: N017 | C21: 2 | D21: choice | E21: Kiến thức | H21: an | I21: neutral | J21: Ngoài kinh tế, hội nhập có thể đem lại lợi ích nào? | L21: Nhập option ở sheet 03 | M21: =IF(A21="","",IF(N21="","HỢP LỆ","CẦN SỬA")) -> HỢP LỆ | N21: =IF(A21="","",IF(B21="","Thiếu NodeId",IF(D21="","Thiếu NodeType",IF(COUNTIF($B$5:$B$204,B21)>1,"NodeId bị trùng",IF(COUNTIF($A$5:$A$204,A21)>1,"NodeOrder bị trùng",IF(AND(D21="scene",OR(C21="",F21="",G21="")),"scene cần ActNo, Background, SceneName",IF(AND(D21="say",OR(H21="",J21="")),"say cần SpeakerKey và Text",IF(AND(D21="choice",OR(E21="",H21="",I21="",J21="")),"choice cần ChoiceMode, SpeakerKey, Mood, Question",IF(AND(D21="act",K21=""),"act cần số La Mã",IF(AND(D21="end",COUNTIF($D$5:$D$204,"end")<>1),"Phải có đúng 1 node end",""))))))))))
A22: 18 | B22: N018 | C22: 2 | D22: choice | E22: Kiến thức | H22: khoa | I22: neutral | J22: Đâu là nhóm tác động tiêu cực và rủi ro kinh tế cần lưu ý? | L22: Nhập option ở sheet 03 | M22: =IF(A22="","",IF(N22="","HỢP LỆ","CẦN SỬA")) -> HỢP LỆ | N22: =IF(A22="","",IF(B22="","Thiếu NodeId",IF(D22="","Thiếu NodeType",IF(COUNTIF($B$5:$B$204,B22)>1,"NodeId bị trùng",IF(COUNTIF($A$5:$A$204,A22)>1,"NodeOrder bị trùng",IF(AND(D22="scene",OR(C22="",F22="",G22="")),"scene cần ActNo, Background, SceneName",IF(AND(D22="say",OR(H22="",J22="")),"say cần SpeakerKey và Text",IF(AND(D22="choice",OR(E22="",H22="",I22="",J22="")),"choice cần ChoiceMode, SpeakerKey, Mood, Question",IF(AND(D22="act",K22=""),"act cần số La Mã",IF(AND(D22="end",COUNTIF($D$5:$D$204,"end")<>1),"Phải có đúng 1 node end",""))))))))))
A23: 19 | B23: N019 | C23: 2 | D23: choice | E23: Kiến thức | H23: lam | I23: neutral | J23: Những thách thức xã hội, văn hóa, môi trường và an ninh nào có thể phát sinh? | L23: Nhập option ở sheet 03 | M23: =IF(A23="","",IF(N23="","HỢP LỆ","CẦN SỬA")) -> HỢP LỆ | N23: =IF(A23="","",IF(B23="","Thiếu NodeId",IF(D23="","Thiếu NodeType",IF(COUNTIF($B$5:$B$204,B23)>1,"NodeId bị trùng",IF(COUNTIF($A$5:$A$204,A23)>1,"NodeOrder bị trùng",IF(AND(D23="scene",OR(C23="",F23="",G23="")),"scene cần ActNo, Background, SceneName",IF(AND(D23="say",OR(H23="",J23="")),"say cần SpeakerKey và Text",IF(AND(D23="choice",OR(E23="",H23="",I23="",J23="")),"choice cần ChoiceMode, SpeakerKey, Mood, Question",IF(AND(D23="act",K23=""),"act cần số La Mã",IF(AND(D23="end",COUNTIF($D$5:$D$204,"end")<>1),"Phải có đúng 1 node end",""))))))))))
A24: 20 | B24: N020 | C24: 2 | D24: choice | E24: Kiến thức | H24: minh | I24: neutral | J24: Vì sao lợi ích hội nhập có thể phân bố không đồng đều? | L24: Nhập option ở sheet 03 | M24: =IF(A24="","",IF(N24="","HỢP LỆ","CẦN SỬA")) -> HỢP LỆ | N24: =IF(A24="","",IF(B24="","Thiếu NodeId",IF(D24="","Thiếu NodeType",IF(COUNTIF($B$5:$B$204,B24)>1,"NodeId bị trùng",IF(COUNTIF($A$5:$A$204,A24)>1,"NodeOrder bị trùng",IF(AND(D24="scene",OR(C24="",F24="",G24="")),"scene cần ActNo, Background, SceneName",IF(AND(D24="say",OR(H24="",J24="")),"say cần SpeakerKey và Text",IF(AND(D24="choice",OR(E24="",H24="",I24="",J24="")),"choice cần ChoiceMode, SpeakerKey, Mood, Question",IF(AND(D24="act",K24=""),"act cần số La Mã",IF(AND(D24="end",COUNTIF($D$5:$D$204,"end")<>1),"Phải có đúng 1 node end",""))))))))))
A25: 21 | B25: N021 | C25: 2 | D25: act | K25: II | L25: Kết thúc màn II | M25: =IF(A25="","",IF(N25="","HỢP LỆ","CẦN SỬA")) -> HỢP LỆ | N25: =IF(A25="","",IF(B25="","Thiếu NodeId",IF(D25="","Thiếu NodeType",IF(COUNTIF($B$5:$B$204,B25)>1,"NodeId bị trùng",IF(COUNTIF($A$5:$A$204,A25)>1,"NodeOrder bị trùng",IF(AND(D25="scene",OR(C25="",F25="",G25="")),"scene cần ActNo, Background, SceneName",IF(AND(D25="say",OR(H25="",J25="")),"say cần SpeakerKey và Text",IF(AND(D25="choice",OR(E25="",H25="",I25="",J25="")),"choice cần ChoiceMode, SpeakerKey, Mood, Question",IF(AND(D25="act",K25=""),"act cần số La Mã",IF(AND(D25="end",COUNTIF($D$5:$D$204,"end")<>1),"Phải có đúng 1 node end",""))))))))))
A26: 22 | B26: N022 | C26: 3 | D26: scene | F26: buctham | G26: Màn III · Nâng cao hiệu quả và giữ vững tự chủ | L26: Bắt đầu màn 3 | M26: =IF(A26="","",IF(N26="","HỢP LỆ","CẦN SỬA")) -> HỢP LỆ | N26: =IF(A26="","",IF(B26="","Thiếu NodeId",IF(D26="","Thiếu NodeType",IF(COUNTIF($B$5:$B$204,B26)>1,"NodeId bị trùng",IF(COUNTIF($A$5:$A$204,A26)>1,"NodeOrder bị trùng",IF(AND(D26="scene",OR(C26="",F26="",G26="")),"scene cần ActNo, Background, SceneName",IF(AND(D26="say",OR(H26="",J26="")),"say cần SpeakerKey và Text",IF(AND(D26="choice",OR(E26="",H26="",I26="",J26="")),"choice cần ChoiceMode, SpeakerKey, Mood, Question",IF(AND(D26="act",K26=""),"act cần số La Mã",IF(AND(D26="end",COUNTIF($D$5:$D$204,"end")<>1),"Phải có đúng 1 node end",""))))))))))
A27: 23 | B27: N023 | C27: 3 | D27: say | H27: narr | J27: Phiên họp chiến lược yêu cầu lựa chọn lộ trình vừa tận dụng nguồn lực quốc tế vừa bảo vệ lợi ích quốc gia và năng lực tự chủ. | M27: =IF(A27="","",IF(N27="","HỢP LỆ","CẦN SỬA")) -> HỢP LỆ | N27: =IF(A27="","",IF(B27="","Thiếu NodeId",IF(D27="","Thiếu NodeType",IF(COUNTIF($B$5:$B$204,B27)>1,"NodeId bị trùng",IF(COUNTIF($A$5:$A$204,A27)>1,"NodeOrder bị trùng",IF(AND(D27="scene",OR(C27="",F27="",G27="")),"scene cần ActNo, Background, SceneName",IF(AND(D27="say",OR(H27="",J27="")),"say cần SpeakerKey và Text",IF(AND(D27="choice",OR(E27="",H27="",I27="",J27="")),"choice cần ChoiceMode, SpeakerKey, Mood, Question",IF(AND(D27="act",K27=""),"act cần số La Mã",IF(AND(D27="end",COUNTIF($D$5:$D$204,"end")<>1),"Phải có đúng 1 node end",""))))))))))
A28: 24 | B28: N024 | C28: 3 | D28: say | H28: lam | I28: neutral | J28: Hội nhập hiệu quả là quá trình chủ động, có chiến lược, dựa trên nội lực và sự tham gia của toàn xã hội. | M28: =IF(A28="","",IF(N28="","HỢP LỆ","CẦN SỬA")) -> HỢP LỆ | N28: =IF(A28="","",IF(B28="","Thiếu NodeId",IF(D28="","Thiếu NodeType",IF(COUNTIF($B$5:$B$204,B28)>1,"NodeId bị trùng",IF(COUNTIF($A$5:$A$204,A28)>1,"NodeOrder bị trùng",IF(AND(D28="scene",OR(C28="",F28="",G28="")),"scene cần ActNo, Background, SceneName",IF(AND(D28="say",OR(H28="",J28="")),"say cần SpeakerKey và Text",IF(AND(D28="choice",OR(E28="",H28="",I28="",J28="")),"choice cần ChoiceMode, SpeakerKey, Mood, Question",IF(AND(D28="act",K28=""),"act cần số La Mã",IF(AND(D28="end",COUNTIF($D$5:$D$204,"end")<>1),"Phải có đúng 1 node end",""))))))))))
A29: 25 | B29: N025 | C29: 3 | D29: choice | E29: Kiến thức | H29: lam | I29: neutral | J29: Yêu cầu đầu tiên để nâng cao hiệu quả hội nhập là gì? | L29: Nhập option ở sheet 03 | M29: =IF(A29="","",IF(N29="","HỢP LỆ","CẦN SỬA")) -> HỢP LỆ | N29: =IF(A29="","",IF(B29="","Thiếu NodeId",IF(D29="","Thiếu NodeType",IF(COUNTIF($B$5:$B$204,B29)>1,"NodeId bị trùng",IF(COUNTIF($A$5:$A$204,A29)>1,"NodeOrder bị trùng",IF(AND(D29="scene",OR(C29="",F29="",G29="")),"scene cần ActNo, Background, SceneName",IF(AND(D29="say",OR(H29="",J29="")),"say cần SpeakerKey và Text",IF(AND(D29="choice",OR(E29="",H29="",I29="",J29="")),"choice cần ChoiceMode, SpeakerKey, Mood, Question",IF(AND(D29="act",K29=""),"act cần số La Mã",IF(AND(D29="end",COUNTIF($D$5:$D$204,"end")<>1),"Phải có đúng 1 node end",""))))))))))
A30: 26 | B30: N026 | C30: 3 | D30: choice | E30: Kiến thức | H30: khoa | I30: neutral | J30: Xây dựng chiến lược và lộ trình hội nhập phù hợp đòi hỏi điều gì? | L30: Nhập option ở sheet 03 | M30: =IF(A30="","",IF(N30="","HỢP LỆ","CẦN SỬA")) -> HỢP LỆ | N30: =IF(A30="","",IF(B30="","Thiếu NodeId",IF(D30="","Thiếu NodeType",IF(COUNTIF($B$5:$B$204,B30)>1,"NodeId bị trùng",IF(COUNTIF($A$5:$A$204,A30)>1,"NodeOrder bị trùng",IF(AND(D30="scene",OR(C30="",F30="",G30="")),"scene cần ActNo, Background, SceneName",IF(AND(D30="say",OR(H30="",J30="")),"say cần SpeakerKey và Text",IF(AND(D30="choice",OR(E30="",H30="",I30="",J30="")),"choice cần ChoiceMode, SpeakerKey, Mood, Question",IF(AND(D30="act",K30=""),"act cần số La Mã",IF(AND(D30="end",COUNTIF($D$5:$D$204,"end")<>1),"Phải có đúng 1 node end",""))))))))))
A31: 27 | B31: N027 | C31: 3 | D31: choice | E31: Kiến thức | H31: an | I31: neutral | J31: Thế nào là tích cực, chủ động tham gia các liên kết kinh tế quốc tế? | L31: Nhập option ở sheet 03 | M31: =IF(A31="","",IF(N31="","HỢP LỆ","CẦN SỬA")) -> HỢP LỆ | N31: =IF(A31="","",IF(B31="","Thiếu NodeId",IF(D31="","Thiếu NodeType",IF(COUNTIF($B$5:$B$204,B31)>1,"NodeId bị trùng",IF(COUNTIF($A$5:$A$204,A31)>1,"NodeOrder bị trùng",IF(AND(D31="scene",OR(C31="",F31="",G31="")),"scene cần ActNo, Background, SceneName",IF(AND(D31="say",OR(H31="",J31="")),"say cần SpeakerKey và Text",IF(AND(D31="choice",OR(E31="",H31="",I31="",J31="")),"choice cần ChoiceMode, SpeakerKey, Mood, Question",IF(AND(D31="act",K31=""),"act cần số La Mã",IF(AND(D31="end",COUNTIF($D$5:$D$204,"end")<>1),"Phải có đúng 1 node end",""))))))))))
A32: 28 | B32: N028 | C32: 3 | D32: choice | E32: Kiến thức | H32: lam | I32: neutral | J32: Hoàn thiện thể chế kinh tế và luật pháp phục vụ hội nhập cần hướng tới điều gì? | L32: Nhập option ở sheet 03 | M32: =IF(A32="","",IF(N32="","HỢP LỆ","CẦN SỬA")) -> HỢP LỆ | N32: =IF(A32="","",IF(B32="","Thiếu NodeId",IF(D32="","Thiếu NodeType",IF(COUNTIF($B$5:$B$204,B32)>1,"NodeId bị trùng",IF(COUNTIF($A$5:$A$204,A32)>1,"NodeOrder bị trùng",IF(AND(D32="scene",OR(C32="",F32="",G32="")),"scene cần ActNo, Background, SceneName",IF(AND(D32="say",OR(H32="",J32="")),"say cần SpeakerKey và Text",IF(AND(D32="choice",OR(E32="",H32="",I32="",J32="")),"choice cần ChoiceMode, SpeakerKey, Mood, Question",IF(AND(D32="act",K32=""),"act cần số La Mã",IF(AND(D32="end",COUNTIF($D$5:$D$204,"end")<>1),"Phải có đúng 1 node end",""))))))))))
A33: 29 | B33: N029 | C33: 3 | D33: choice | E33: Kiến thức | H33: khoa | I33: neutral | J33: Nâng cao năng lực cạnh tranh quốc tế cần tập trung vào đâu? | L33: Nhập option ở sheet 03 | M33: =IF(A33="","",IF(N33="","HỢP LỆ","CẦN SỬA")) -> HỢP LỆ | N33: =IF(A33="","",IF(B33="","Thiếu NodeId",IF(D33="","Thiếu NodeType",IF(COUNTIF($B$5:$B$204,B33)>1,"NodeId bị trùng",IF(COUNTIF($A$5:$A$204,A33)>1,"NodeOrder bị trùng",IF(AND(D33="scene",OR(C33="",F33="",G33="")),"scene cần ActNo, Background, SceneName",IF(AND(D33="say",OR(H33="",J33="")),"say cần SpeakerKey và Text",IF(AND(D33="choice",OR(E33="",H33="",I33="",J33="")),"choice cần ChoiceMode, SpeakerKey, Mood, Question",IF(AND(D33="act",K33=""),"act cần số La Mã",IF(AND(D33="end",COUNTIF($D$5:$D$204,"end")<>1),"Phải có đúng 1 node end",""))))))))))
A34: 30 | B34: N030 | C34: 3 | D34: choice | E34: Kiến thức | H34: an | I34: neutral | J34: Xây dựng nền kinh tế độc lập, tự chủ trong hội nhập được hiểu như thế nào? | L34: Nhập option ở sheet 03 | M34: =IF(A34="","",IF(N34="","HỢP LỆ","CẦN SỬA")) -> HỢP LỆ | N34: =IF(A34="","",IF(B34="","Thiếu NodeId",IF(D34="","Thiếu NodeType",IF(COUNTIF($B$5:$B$204,B34)>1,"NodeId bị trùng",IF(COUNTIF($A$5:$A$204,A34)>1,"NodeOrder bị trùng",IF(AND(D34="scene",OR(C34="",F34="",G34="")),"scene cần ActNo, Background, SceneName",IF(AND(D34="say",OR(H34="",J34="")),"say cần SpeakerKey và Text",IF(AND(D34="choice",OR(E34="",H34="",I34="",J34="")),"choice cần ChoiceMode, SpeakerKey, Mood, Question",IF(AND(D34="act",K34=""),"act cần số La Mã",IF(AND(D34="end",COUNTIF($D$5:$D$204,"end")<>1),"Phải có đúng 1 node end",""))))))))))
A35: 31 | B35: N031 | C35: 3 | D35: choice | E35: Kiến thức | H35: lam | I35: neutral | J35: Mối quan hệ giữa độc lập, tự chủ và hội nhập được xử lý như thế nào? | L35: Nhập option ở sheet 03 | M35: =IF(A35="","",IF(N35="","HỢP LỆ","CẦN SỬA")) -> HỢP LỆ | N35: =IF(A35="","",IF(B35="","Thiếu NodeId",IF(D35="","Thiếu NodeType",IF(COUNTIF($B$5:$B$204,B35)>1,"NodeId bị trùng",IF(COUNTIF($A$5:$A$204,A35)>1,"NodeOrder bị trùng",IF(AND(D35="scene",OR(C35="",F35="",G35="")),"scene cần ActNo, Background, SceneName",IF(AND(D35="say",OR(H35="",J35="")),"say cần SpeakerKey và Text",IF(AND(D35="choice",OR(E35="",H35="",I35="",J35="")),"choice cần ChoiceMode, SpeakerKey, Mood, Question",IF(AND(D35="act",K35=""),"act cần số La Mã",IF(AND(D35="end",COUNTIF($D$5:$D$204,"end")<>1),"Phải có đúng 1 node end",""))))))))))
A36: 32 | B36: N032 | C36: 3 | D36: choice | E36: Kiến thức | H36: minh | I36: neutral | J36: Doanh nghiệp Việt Nam cần làm gì để tận dụng hội nhập? | L36: Nhập option ở sheet 03 | M36: =IF(A36="","",IF(N36="","HỢP LỆ","CẦN SỬA")) -> HỢP LỆ | N36: =IF(A36="","",IF(B36="","Thiếu NodeId",IF(D36="","Thiếu NodeType",IF(COUNTIF($B$5:$B$204,B36)>1,"NodeId bị trùng",IF(COUNTIF($A$5:$A$204,A36)>1,"NodeOrder bị trùng",IF(AND(D36="scene",OR(C36="",F36="",G36="")),"scene cần ActNo, Background, SceneName",IF(AND(D36="say",OR(H36="",J36="")),"say cần SpeakerKey và Text",IF(AND(D36="choice",OR(E36="",H36="",I36="",J36="")),"choice cần ChoiceMode, SpeakerKey, Mood, Question",IF(AND(D36="act",K36=""),"act cần số La Mã",IF(AND(D36="end",COUNTIF($D$5:$D$204,"end")<>1),"Phải có đúng 1 node end",""))))))))))
A37: 33 | B37: N033 | C37: 3 | D37: say | H37: lam | I37: happy | J37: Bạn đã hoàn thành mục 6.2: bản chất, tác động hai mặt và các phương hướng nâng cao hiệu quả hội nhập kinh tế quốc tế. | M37: =IF(A37="","",IF(N37="","HỢP LỆ","CẦN SỬA")) -> HỢP LỆ | N37: =IF(A37="","",IF(B37="","Thiếu NodeId",IF(D37="","Thiếu NodeType",IF(COUNTIF($B$5:$B$204,B37)>1,"NodeId bị trùng",IF(COUNTIF($A$5:$A$204,A37)>1,"NodeOrder bị trùng",IF(AND(D37="scene",OR(C37="",F37="",G37="")),"scene cần ActNo, Background, SceneName",IF(AND(D37="say",OR(H37="",J37="")),"say cần SpeakerKey và Text",IF(AND(D37="choice",OR(E37="",H37="",I37="",J37="")),"choice cần ChoiceMode, SpeakerKey, Mood, Question",IF(AND(D37="act",K37=""),"act cần số La Mã",IF(AND(D37="end",COUNTIF($D$5:$D$204,"end")<>1),"Phải có đúng 1 node end",""))))))))))
A38: 34 | B38: N034 | C38: 3 | D38: act | K38: III | L38: Kết thúc màn III | M38: =IF(A38="","",IF(N38="","HỢP LỆ","CẦN SỬA")) -> HỢP LỆ | N38: =IF(A38="","",IF(B38="","Thiếu NodeId",IF(D38="","Thiếu NodeType",IF(COUNTIF($B$5:$B$204,B38)>1,"NodeId bị trùng",IF(COUNTIF($A$5:$A$204,A38)>1,"NodeOrder bị trùng",IF(AND(D38="scene",OR(C38="",F38="",G38="")),"scene cần ActNo, Background, SceneName",IF(AND(D38="say",OR(H38="",J38="")),"say cần SpeakerKey và Text",IF(AND(D38="choice",OR(E38="",H38="",I38="",J38="")),"choice cần ChoiceMode, SpeakerKey, Mood, Question",IF(AND(D38="act",K38=""),"act cần số La Mã",IF(AND(D38="end",COUNTIF($D$5:$D$204,"end")<>1),"Phải có đúng 1 node end",""))))))))))
A39: 35 | B39: N035 | D39: end | L39: Kết thúc toàn bộ game | M39: =IF(A39="","",IF(N39="","HỢP LỆ","CẦN SỬA")) -> HỢP LỆ | N39: =IF(A39="","",IF(B39="","Thiếu NodeId",IF(D39="","Thiếu NodeType",IF(COUNTIF($B$5:$B$204,B39)>1,"NodeId bị trùng",IF(COUNTIF($A$5:$A$204,A39)>1,"NodeOrder bị trùng",IF(AND(D39="scene",OR(C39="",F39="",G39="")),"scene cần ActNo, Background, SceneName",IF(AND(D39="say",OR(H39="",J39="")),"say cần SpeakerKey và Text",IF(AND(D39="choice",OR(E39="",H39="",I39="",J39="")),"choice cần ChoiceMode, SpeakerKey, Mood, Question",IF(AND(D39="act",K39=""),"act cần số La Mã",IF(AND(D39="end",COUNTIF($D$5:$D$204,"end")<>1),"Phải có đúng 1 node end",""))))))))))
M40: =IF(A40="","",IF(N40="","HỢP LỆ","CẦN SỬA")) | N40: =IF(A40="","",IF(B40="","Thiếu NodeId",IF(D40="","Thiếu NodeType",IF(COUNTIF($B$5:$B$204,B40)>1,"NodeId bị trùng",IF(COUNTIF($A$5:$A$204,A40)>1,"NodeOrder bị trùng",IF(AND(D40="scene",OR(C40="",F40="",G40="")),"scene cần ActNo, Background, SceneName",IF(AND(D40="say",OR(H40="",J40="")),"say cần SpeakerKey và Text",IF(AND(D40="choice",OR(E40="",H40="",I40="",J40="")),"choice cần ChoiceMode, SpeakerKey, Mood, Question",IF(AND(D40="act",K40=""),"act cần số La Mã",IF(AND(D40="end",COUNTIF($D$5:$D$204,"end")<>1),"Phải có đúng 1 node end",""))))))))))
M41: =IF(A41="","",IF(N41="","HỢP LỆ","CẦN SỬA")) | N41: =IF(A41="","",IF(B41="","Thiếu NodeId",IF(D41="","Thiếu NodeType",IF(COUNTIF($B$5:$B$204,B41)>1,"NodeId bị trùng",IF(COUNTIF($A$5:$A$204,A41)>1,"NodeOrder bị trùng",IF(AND(D41="scene",OR(C41="",F41="",G41="")),"scene cần ActNo, Background, SceneName",IF(AND(D41="say",OR(H41="",J41="")),"say cần SpeakerKey và Text",IF(AND(D41="choice",OR(E41="",H41="",I41="",J41="")),"choice cần ChoiceMode, SpeakerKey, Mood, Question",IF(AND(D41="act",K41=""),"act cần số La Mã",IF(AND(D41="end",COUNTIF($D$5:$D$204,"end")<>1),"Phải có đúng 1 node end",""))))))))))
...

Sheet 03_LUA_CHON
A1: 03 — PHƯƠNG ÁN CHO CÁC NODE CHOICE
A2: Choice kiến thức: đúng 1 đáp án. Choice tương tác: không có đáp án đúng, có thể nhập dc để thay đổi thiện cảm.
A4: ChoiceNodeId* | B4: OptionOrder* | C4: OptionText* | D4: IsCorrect* | E4: dc | F4: ReplySpeaker* | G4: ReplyMood | H4: ReplyText* | I4: Ghi chú | J4: Trạng thái | K4: Lỗi cấu trúc
A5: N004 | B5: 1 | C5: Đi từ khái niệm, tính tất yếu đến các hình thức và mức độ hội nhập. | D5: Không | E5: 8 | F5: lam | G5: happy | H5: Tốt. Ta sẽ xây dựng bản đồ hội nhập từ nền tảng đến các cấp độ liên kết. | I5: Choice tương tác | J5: =IF(A5="","",IF(K5="","HỢP LỆ","CẦN SỬA")) -> HỢP LỆ | K5: =IF(A5="","",IF(COUNTIFS('02_KICH_BAN_NODES'!$B$5:$B$204,A5,'02_KICH_BAN_NODES'!$D$5:$D$204,"choice")=0,"ChoiceNodeId không tồn tại hoặc không phải choice",IF(COUNTIFS($A$5:$A$404,A5,$B$5:$B$404,B5)>1,"Trùng OptionOrder trong cùng choice",IF(OR(B5="",C5="",D5="",F5="",H5=""),"Thiếu trường bắt buộc",IF(OR(COUNTIF($A$5:$A$404,A5)<2,COUNTIF($A$5:$A$404,A5)>4),"Mỗi choice cần 2–4 option",IF(COUNTIFS('02_KICH_BAN_NODES'!$B$5:$B$204,A5,'02_KICH_BAN_NODES'!$E$5:$E$204,"Kiến thức")=1,IF(COUNTIFS($A$5:$A$404,A5,$D$5:$D$404,"Có")<>1,"Choice kiến thức cần đúng 1 đáp án đúng",""),IF(COUNTIFS('02_KICH_BAN_NODES'!$B$5:$B$204,A5,'02_KICH_BAN_NODES'!$E$5:$E$204,"Tương tác")=1,IF(COUNTIFS($A$5:$A$404,A5,$D$5:$D$404,"Có")<>0,"Choice tương tác không được đánh dấu đáp án đúng",""),"Choice chưa chọn loại")))))))
A6: N004 | B6: 2 | C6: Phân tích cơ hội, rủi ro trước rồi quay lại cơ sở lý luận. | D6: Không | E6: 4 | F6: lam | G6: neutral | H6: Được. Cơ hội và thách thức chỉ được hiểu đúng khi nắm bản chất hội nhập. | I6: Choice tương tác | J6: =IF(A6="","",IF(K6="","HỢP LỆ","CẦN SỬA")) -> HỢP LỆ | K6: =IF(A6="","",IF(COUNTIFS('02_KICH_BAN_NODES'!$B$5:$B$204,A6,'02_KICH_BAN_NODES'!$D$5:$D$204,"choice")=0,"ChoiceNodeId không tồn tại hoặc không phải choice",IF(COUNTIFS($A$5:$A$404,A6,$B$5:$B$404,B6)>1,"Trùng OptionOrder trong cùng choice",IF(OR(B6="",C6="",D6="",F6="",H6=""),"Thiếu trường bắt buộc",IF(OR(COUNTIF($A$5:$A$404,A6)<2,COUNTIF($A$5:$A$404,A6)>4),"Mỗi choice cần 2–4 option",IF(COUNTIFS('02_KICH_BAN_NODES'!$B$5:$B$204,A6,'02_KICH_BAN_NODES'!$E$5:$E$204,"Kiến thức")=1,IF(COUNTIFS($A$5:$A$404,A6,$D$5:$D$404,"Có")<>1,"Choice kiến thức cần đúng 1 đáp án đúng",""),IF(COUNTIFS('02_KICH_BAN_NODES'!$B$5:$B$204,A6,'02_KICH_BAN_NODES'!$E$5:$E$204,"Tương tác")=1,IF(COUNTIFS($A$5:$A$404,A6,$D$5:$D$404,"Có")<>0,"Choice tương tác không được đánh dấu đáp án đúng",""),"Choice chưa chọn loại")))))))
A7: N005 | B7: 1 | C7: Quá trình quốc gia gắn kết nền kinh tế của mình với kinh tế thế giới dựa trên chia sẻ lợi ích, tuân thủ chuẩn mực chung và tham gia phân công lao động quốc tế. | D7: Có | F7: an | G7: happy | H7: Chính xác. Hội nhập bao gồm thương mại, đầu tư, dịch vụ, tài chính, công nghệ và các quan hệ khác. | I7: Đáp án đúng | J7: =IF(A7="","",IF(K7="","HỢP LỆ","CẦN SỬA")) -> HỢP LỆ | K7: =IF(A7="","",IF(COUNTIFS('02_KICH_BAN_NODES'!$B$5:$B$204,A7,'02_KICH_BAN_NODES'!$D$5:$D$204,"choice")=0,"ChoiceNodeId không tồn tại hoặc không phải choice",IF(COUNTIFS($A$5:$A$404,A7,$B$5:$B$404,B7)>1,"Trùng OptionOrder trong cùng choice",IF(OR(B7="",C7="",D7="",F7="",H7=""),"Thiếu trường bắt buộc",IF(OR(COUNTIF($A$5:$A$404,A7)<2,COUNTIF($A$5:$A$404,A7)>4),"Mỗi choice cần 2–4 option",IF(COUNTIFS('02_KICH_BAN_NODES'!$B$5:$B$204,A7,'02_KICH_BAN_NODES'!$E$5:$E$204,"Kiến thức")=1,IF(COUNTIFS($A$5:$A$404,A7,$D$5:$D$404,"Có")<>1,"Choice kiến thức cần đúng 1 đáp án đúng",""),IF(COUNTIFS('02_KICH_BAN_NODES'!$B$5:$B$204,A7,'02_KICH_BAN_NODES'!$E$5:$E$204,"Tương tác")=1,IF(COUNTIFS($A$5:$A$404,A7,$D$5:$D$404,"Có")<>0,"Choice tương tác không được đánh dấu đáp án đúng",""),"Choice chưa chọn loại")))))))
A8: N005 | B8: 2 | C8: Chỉ là tăng xuất khẩu hàng hóa. | D8: Không | F8: an | G8: concern | H8: Chưa đúng. Hội nhập bao gồm thương mại, đầu tư, dịch vụ, tài chính, công nghệ và các quan hệ khác. | I8: Đáp án nhiễu | J8: =IF(A8="","",IF(K8="","HỢP LỆ","CẦN SỬA")) -> HỢP LỆ | K8: =IF(A8="","",IF(COUNTIFS('02_KICH_BAN_NODES'!$B$5:$B$204,A8,'02_KICH_BAN_NODES'!$D$5:$D$204,"choice")=0,"ChoiceNodeId không tồn tại hoặc không phải choice",IF(COUNTIFS($A$5:$A$404,A8,$B$5:$B$404,B8)>1,"Trùng OptionOrder trong cùng choice",IF(OR(B8="",C8="",D8="",F8="",H8=""),"Thiếu trường bắt buộc",IF(OR(COUNTIF($A$5:$A$404,A8)<2,COUNTIF($A$5:$A$404,A8)>4),"Mỗi choice cần 2–4 option",IF(COUNTIFS('02_KICH_BAN_NODES'!$B$5:$B$204,A8,'02_KICH_BAN_NODES'!$E$5:$E$204,"Kiến thức")=1,IF(COUNTIFS($A$5:$A$404,A8,$D$5:$D$404,"Có")<>1,"Choice kiến thức cần đúng 1 đáp án đúng",""),IF(COUNTIFS('02_KICH_BAN_NODES'!$B$5:$B$204,A8,'02_KICH_BAN_NODES'!$E$5:$E$204,"Tương tác")=1,IF(COUNTIFS($A$5:$A$404,A8,$D$5:$D$404,"Có")<>0,"Choice tương tác không được đánh dấu đáp án đúng",""),"Choice chưa chọn loại")))))))
A9: N005 | B9: 3 | C9: Là từ bỏ hoàn toàn quyền tự chủ. | D9: Không | F9: an | G9: concern | H9: Chưa đúng. Hội nhập bao gồm thương mại, đầu tư, dịch vụ, tài chính, công nghệ và các quan hệ khác. | I9: Đáp án nhiễu | J9: =IF(A9="","",IF(K9="","HỢP LỆ","CẦN SỬA")) -> HỢP LỆ | K9: =IF(A9="","",IF(COUNTIFS('02_KICH_BAN_NODES'!$B$5:$B$204,A9,'02_KICH_BAN_NODES'!$D$5:$D$204,"choice")=0,"ChoiceNodeId không tồn tại hoặc không phải choice",IF(COUNTIFS($A$5:$A$404,A9,$B$5:$B$404,B9)>1,"Trùng OptionOrder trong cùng choice",IF(OR(B9="",C9="",D9="",F9="",H9=""),"Thiếu trường bắt buộc",IF(OR(COUNTIF($A$5:$A$404,A9)<2,COUNTIF($A$5:$A$404,A9)>4),"Mỗi choice cần 2–4 option",IF(COUNTIFS('02_KICH_BAN_NODES'!$B$5:$B$204,A9,'02_KICH_BAN_NODES'!$E$5:$E$204,"Kiến thức")=1,IF(COUNTIFS($A$5:$A$404,A9,$D$5:$D$404,"Có")<>1,"Choice kiến thức cần đúng 1 đáp án đúng",""),IF(COUNTIFS('02_KICH_BAN_NODES'!$B$5:$B$204,A9,'02_KICH_BAN_NODES'!$E$5:$E$204,"Tương tác")=1,IF(COUNTIFS($A$5:$A$404,A9,$D$5:$D$404,"Có")<>0,"Choice tương tác không được đánh dấu đáp án đúng",""),"Choice chưa chọn loại")))))))
A10: N006 | B10: 1 | C10: Do toàn cầu hóa và phân công lao động quốc tế làm các nền kinh tế ngày càng liên hệ, phụ thuộc lẫn nhau; hội nhập giúp tiếp cận thị trường và nguồn lực. | D10: Có | F10: lam | G10: happy | H10: Chính xác. Đứng ngoài xu thế có thể làm mất cơ hội, nhưng hội nhập phải có chiến lược và năng lực nội tại. | I10: Đáp án đúng | J10: =IF(A10="","",IF(K10="","HỢP LỆ","CẦN SỬA")) -> HỢP LỆ | K10: =IF(A10="","",IF(COUNTIFS('02_KICH_BAN_NODES'!$B$5:$B$204,A10,'02_KICH_BAN_NODES'!$D$5:$D$204,"choice")=0,"ChoiceNodeId không tồn tại hoặc không phải choice",IF(COUNTIFS($A$5:$A$404,A10,$B$5:$B$404,B10)>1,"Trùng OptionOrder trong cùng choice",IF(OR(B10="",C10="",D10="",F10="",H10=""),"Thiếu trường bắt buộc",IF(OR(COUNTIF($A$5:$A$404,A10)<2,COUNTIF($A$5:$A$404,A10)>4),"Mỗi choice cần 2–4 option",IF(COUNTIFS('02_KICH_BAN_NODES'!$B$5:$B$204,A10,'02_KICH_BAN_NODES'!$E$5:$E$204,"Kiến thức")=1,IF(COUNTIFS($A$5:$A$404,A10,$D$5:$D$404,"Có")<>1,"Choice kiến thức cần đúng 1 đáp án đúng",""),IF(COUNTIFS('02_KICH_BAN_NODES'!$B$5:$B$204,A10,'02_KICH_BAN_NODES'!$E$5:$E$204,"Tương tác")=1,IF(COUNTIFS($A$5:$A$404,A10,$D$5:$D$404,"Có")<>0,"Choice tương tác không được đánh dấu đáp án đúng",""),"Choice chưa chọn loại")))))))
A11: N006 | B11: 2 | C11: Vì mọi quốc gia phải từ bỏ lợi ích riêng. | D11: Không | F11: lam | G11: concern | H11: Chưa đúng. Đứng ngoài xu thế có thể làm mất cơ hội, nhưng hội nhập phải có chiến lược và năng lực nội tại. | I11: Đáp án nhiễu | J11: =IF(A11="","",IF(K11="","HỢP LỆ","CẦN SỬA")) -> HỢP LỆ | K11: =IF(A11="","",IF(COUNTIFS('02_KICH_BAN_NODES'!$B$5:$B$204,A11,'02_KICH_BAN_NODES'!$D$5:$D$204,"choice")=0,"ChoiceNodeId không tồn tại hoặc không phải choice",IF(COUNTIFS($A$5:$A$404,A11,$B$5:$B$404,B11)>1,"Trùng OptionOrder trong cùng choice",IF(OR(B11="",C11="",D11="",F11="",H11=""),"Thiếu trường bắt buộc",IF(OR(COUNTIF($A$5:$A$404,A11)<2,COUNTIF($A$5:$A$404,A11)>4),"Mỗi choice cần 2–4 option",IF(COUNTIFS('02_KICH_BAN_NODES'!$B$5:$B$204,A11,'02_KICH_BAN_NODES'!$E$5:$E$204,"Kiến thức")=1,IF(COUNTIFS($A$5:$A$404,A11,$D$5:$D$404,"Có")<>1,"Choice kiến thức cần đúng 1 đáp án đúng",""),IF(COUNTIFS('02_KICH_BAN_NODES'!$B$5:$B$204,A11,'02_KICH_BAN_NODES'!$E$5:$E$204,"Tương tác")=1,IF(COUNTIFS($A$5:$A$404,A11,$D$5:$D$404,"Có")<>0,"Choice tương tác không được đánh dấu đáp án đúng",""),"Choice chưa chọn loại")))))))
A12: N006 | B12: 3 | C12: Vì hội nhập luôn đem lại lợi ích tự động và không có rủi ro. | D12: Không | F12: lam | G12: concern | H12: Chưa đúng. Đứng ngoài xu thế có thể làm mất cơ hội, nhưng hội nhập phải có chiến lược và năng lực nội tại. | I12: Đáp án nhiễu | J12: =IF(A12="","",IF(K12="","HỢP LỆ","CẦN SỬA")) -> HỢP LỆ | K12: =IF(A12="","",IF(COUNTIFS('02_KICH_BAN_NODES'!$B$5:$B$204,A12,'02_KICH_BAN_NODES'!$D$5:$D$204,"choice")=0,"ChoiceNodeId không tồn tại hoặc không phải choice",IF(COUNTIFS($A$5:$A$404,A12,$B$5:$B$404,B12)>1,"Trùng OptionOrder trong cùng choice",IF(OR(B12="",C12="",D12="",F12="",H12=""),"Thiếu trường bắt buộc",IF(OR(COUNTIF($A$5:$A$404,A12)<2,COUNTIF($A$5:$A$404,A12)>4),"Mỗi choice cần 2–4 option",IF(COUNTIFS('02_KICH_BAN_NODES'!$B$5:$B$204,A12,'02_KICH_BAN_NODES'!$E$5:$E$204,"Kiến thức")=1,IF(COUNTIFS($A$5:$A$404,A12,$D$5:$D$404,"Có")<>1,"Choice kiến thức cần đúng 1 đáp án đúng",""),IF(COUNTIFS('02_KICH_BAN_NODES'!$B$5:$B$204,A12,'02_KICH_BAN_NODES'!$E$5:$E$204,"Tương tác")=1,IF(COUNTIFS($A$5:$A$404,A12,$D$5:$D$404,"Có")<>0,"Choice tương tác không được đánh dấu đáp án đúng",""),"Choice chưa chọn loại")))))))
A13: N007 | B13: 1 | C13: Chuẩn bị điều kiện trong nước; tham gia các liên kết, tổ chức kinh tế quốc tế; thực hiện cam kết và điều chỉnh thể chế. | D13: Có | F13: khoa | G13: neutral | H13: Chính xác. Hội nhập là quá trình vừa đối ngoại vừa cải cách bên trong nền kinh tế. | I13: Đáp án đúng | J13: =IF(A13="","",IF(K13="","HỢP LỆ","CẦN SỬA")) -> HỢP LỆ | K13: =IF(A13="","",IF(COUNTIFS('02_KICH_BAN_NODES'!$B$5:$B$204,A13,'02_KICH_BAN_NODES'!$D$5:$D$204,"choice")=0,"ChoiceNodeId không tồn tại hoặc không phải choice",IF(COUNTIFS($A$5:$A$404,A13,$B$5:$B$404,B13)>1,"Trùng OptionOrder trong cùng choice",IF(OR(B13="",C13="",D13="",F13="",H13=""),"Thiếu trường bắt buộc",IF(OR(COUNTIF($A$5:$A$404,A13)<2,COUNTIF($A$5:$A$404,A13)>4),"Mỗi choice cần 2–4 option",IF(COUNTIFS('02_KICH_BAN_NODES'!$B$5:$B$204,A13,'02_KICH_BAN_NODES'!$E$5:$E$204,"Kiến thức")=1,IF(COUNTIFS($A$5:$A$404,A13,$D$5:$D$404,"Có")<>1,"Choice kiến thức cần đúng 1 đáp án đúng",""),IF(COUNTIFS('02_KICH_BAN_NODES'!$B$5:$B$204,A13,'02_KICH_BAN_NODES'!$E$5:$E$204,"Tương tác")=1,IF(COUNTIFS($A$5:$A$404,A13,$D$5:$D$404,"Có")<>0,"Choice tương tác không được đánh dấu đáp án đúng",""),"Choice chưa chọn loại")))))))
A14: N007 | B14: 2 | C14: Chỉ ký văn bản đối ngoại, không cần cải cách trong nước. | D14: Không | F14: khoa | G14: stern | H14: Chưa đúng. Hội nhập là quá trình vừa đối ngoại vừa cải cách bên trong nền kinh tế. | I14: Đáp án nhiễu | J14: =IF(A14="","",IF(K14="","HỢP LỆ","CẦN SỬA")) -> HỢP LỆ | K14: =IF(A14="","",IF(COUNTIFS('02_KICH_BAN_NODES'!$B$5:$B$204,A14,'02_KICH_BAN_NODES'!$D$5:$D$204,"choice")=0,"ChoiceNodeId không tồn tại hoặc không phải choice",IF(COUNTIFS($A$5:$A$404,A14,$B$5:$B$404,B14)>1,"Trùng OptionOrder trong cùng choice",IF(OR(B14="",C14="",D14="",F14="",H14=""),"Thiếu trường bắt buộc",IF(OR(COUNTIF($A$5:$A$404,A14)<2,COUNTIF($A$5:$A$404,A14)>4),"Mỗi choice cần 2–4 option",IF(COUNTIFS('02_KICH_BAN_NODES'!$B$5:$B$204,A14,'02_KICH_BAN_NODES'!$E$5:$E$204,"Kiến thức")=1,IF(COUNTIFS($A$5:$A$404,A14,$D$5:$D$404,"Có")<>1,"Choice kiến thức cần đúng 1 đáp án đúng",""),IF(COUNTIFS('02_KICH_BAN_NODES'!$B$5:$B$204,A14,'02_KICH_BAN_NODES'!$E$5:$E$204,"Tương tác")=1,IF(COUNTIFS($A$5:$A$404,A14,$D$5:$D$404,"Có")<>0,"Choice tương tác không được đánh dấu đáp án đúng",""),"Choice chưa chọn loại")))))))
A15: N007 | B15: 3 | C15: Chỉ mở cửa nhập khẩu. | D15: Không | F15: khoa | G15: stern | H15: Chưa đúng. Hội nhập là quá trình vừa đối ngoại vừa cải cách bên trong nền kinh tế. | I15: Đáp án nhiễu | J15: =IF(A15="","",IF(K15="","HỢP LỆ","CẦN SỬA")) -> HỢP LỆ | K15: =IF(A15="","",IF(COUNTIFS('02_KICH_BAN_NODES'!$B$5:$B$204,A15,'02_KICH_BAN_NODES'!$D$5:$D$204,"choice")=0,"ChoiceNodeId không tồn tại hoặc không phải choice",IF(COUNTIFS($A$5:$A$404,A15,$B$5:$B$404,B15)>1,"Trùng OptionOrder trong cùng choice",IF(OR(B15="",C15="",D15="",F15="",H15=""),"Thiếu trường bắt buộc",IF(OR(COUNTIF($A$5:$A$404,A15)<2,COUNTIF($A$5:$A$404,A15)>4),"Mỗi choice cần 2–4 option",IF(COUNTIFS('02_KICH_BAN_NODES'!$B$5:$B$204,A15,'02_KICH_BAN_NODES'!$E$5:$E$204,"Kiến thức")=1,IF(COUNTIFS($A$5:$A$404,A15,$D$5:$D$404,"Có")<>1,"Choice kiến thức cần đúng 1 đáp án đúng",""),IF(COUNTIFS('02_KICH_BAN_NODES'!$B$5:$B$204,A15,'02_KICH_BAN_NODES'!$E$5:$E$204,"Tương tác")=1,IF(COUNTIFS($A$5:$A$404,A15,$D$5:$D$404,"Có")<>0,"Choice tương tác không được đánh dấu đáp án đúng",""),"Choice chưa chọn loại")))))))
A16: N008 | B16: 1 | C16: Song phương, khu vực và toàn cầu thông qua thương mại, đầu tư, hợp tác kinh tế, hiệp định và tổ chức quốc tế. | D16: Có | F16: an | G16: happy | H16: Chính xác. Các hình thức hội nhập có thể tồn tại đồng thời và bổ sung cho nhau. | I16: Đáp án đúng | J16: =IF(A16="","",IF(K16="","HỢP LỆ","CẦN SỬA")) -> HỢP LỆ | K16: =IF(A16="","",IF(COUNTIFS('02_KICH_BAN_NODES'!$B$5:$B$204,A16,'02_KICH_BAN_NODES'!$D$5:$D$204,"choice")=0,"ChoiceNodeId không tồn tại hoặc không phải choice",IF(COUNTIFS($A$5:$A$404,A16,$B$5:$B$404,B16)>1,"Trùng OptionOrder trong cùng choice",IF(OR(B16="",C16="",D16="",F16="",H16=""),"Thiếu trường bắt buộc",IF(OR(COUNTIF($A$5:$A$404,A16)<2,COUNTIF($A$5:$A$404,A16)>4),"Mỗi choice cần 2–4 option",IF(COUNTIFS('02_KICH_BAN_NODES'!$B$5:$B$204,A16,'02_KICH_BAN_NODES'!$E$5:$E$204,"Kiến thức")=1,IF(COUNTIFS($A$5:$A$404,A16,$D$5:$D$404,"Có")<>1,"Choice kiến thức cần đúng 1 đáp án đúng",""),IF(COUNTIFS('02_KICH_BAN_NODES'!$B$5:$B$204,A16,'02_KICH_BAN_NODES'!$E$5:$E$204,"Tương tác")=1,IF(COUNTIFS($A$5:$A$404,A16,$D$5:$D$404,"Có")<>0,"Choice tương tác không được đánh dấu đáp án đúng",""),"Choice chưa chọn loại")))))))
A17: N008 | B17: 2 | C17: Chỉ có hội nhập toàn cầu. | D17: Không | F17: an | G17: concern | H17: Chưa đúng. Các hình thức hội nhập có thể tồn tại đồng thời và bổ sung cho nhau. | I17: Đáp án nhiễu | J17: =IF(A17="","",IF(K17="","HỢP LỆ","CẦN SỬA")) -> HỢP LỆ | K17: =IF(A17="","",IF(COUNTIFS('02_KICH_BAN_NODES'!$B$5:$B$204,A17,'02_KICH_BAN_NODES'!$D$5:$D$204,"choice")=0,"ChoiceNodeId không tồn tại hoặc không phải choice",IF(COUNTIFS($A$5:$A$404,A17,$B$5:$B$404,B17)>1,"Trùng OptionOrder trong cùng choice",IF(OR(B17="",C17="",D17="",F17="",H17=""),"Thiếu trường bắt buộc",IF(OR(COUNTIF($A$5:$A$404,A17)<2,COUNTIF($A$5:$A$404,A17)>4),"Mỗi choice cần 2–4 option",IF(COUNTIFS('02_KICH_BAN_NODES'!$B$5:$B$204,A17,'02_KICH_BAN_NODES'!$E$5:$E$204,"Kiến thức")=1,IF(COUNTIFS($A$5:$A$404,A17,$D$5:$D$404,"Có")<>1,"Choice kiến thức cần đúng 1 đáp án đúng",""),IF(COUNTIFS('02_KICH_BAN_NODES'!$B$5:$B$204,A17,'02_KICH_BAN_NODES'!$E$5:$E$204,"Tương tác")=1,IF(COUNTIFS($A$5:$A$404,A17,$D$5:$D$404,"Có")<>0,"Choice tương tác không được đánh dấu đáp án đúng",""),"Choice chưa chọn loại")))))))
A18: N008 | B18: 3 | C18: Chỉ có quan hệ ngoại giao chính trị. | D18: Không | F18: an | G18: concern | H18: Chưa đúng. Các hình thức hội nhập có thể tồn tại đồng thời và bổ sung cho nhau. | I18: Đáp án nhiễu | J18: =IF(A18="","",IF(K18="","HỢP LỆ","CẦN SỬA")) -> HỢP LỆ | K18: =IF(A18="","",IF(COUNTIFS('02_KICH_BAN_NODES'!$B$5:$B$204,A18,'02_KICH_BAN_NODES'!$D$5:$D$204,"choice")=0,"ChoiceNodeId không tồn tại hoặc không phải choice",IF(COUNTIFS($A$5:$A$404,A18,$B$5:$B$404,B18)>1,"Trùng OptionOrder trong cùng choice",IF(OR(B18="",C18="",D18="",F18="",H18=""),"Thiếu trường bắt buộc",IF(OR(COUNTIF($A$5:$A$404,A18)<2,COUNTIF($A$5:$A$404,A18)>4),"Mỗi choice cần 2–4 option",IF(COUNTIFS('02_KICH_BAN_NODES'!$B$5:$B$204,A18,'02_KICH_BAN_NODES'!$E$5:$E$204,"Kiến thức")=1,IF(COUNTIFS($A$5:$A$404,A18,$D$5:$D$404,"Có")<>1,"Choice kiến thức cần đúng 1 đáp án đúng",""),IF(COUNTIFS('02_KICH_BAN_NODES'!$B$5:$B$204,A18,'02_KICH_BAN_NODES'!$E$5:$E$204,"Tương tác")=1,IF(COUNTIFS($A$5:$A$404,A18,$D$5:$D$404,"Có")<>0,"Choice tương tác không được đánh dấu đáp án đúng",""),"Choice chưa chọn loại")))))))
... A66: N032 | B66: 3 | C66: Cạnh tranh chủ yếu bằng giảm lương, bỏ qua chất lượng và môi trường. | D66: Không | F66: minh | G66: concern | H66: Chưa đúng. Doanh nghiệp là lực lượng trực tiếp biến cơ hội thị trường thành giá trị gia tăng. | I66: Đáp án nhiễu | J66: =IF(A66="","",IF(K66="","HỢP LỆ","CẦN SỬA")) -> HỢP LỆ | K66: =IF(A66="","",IF(COUNTIFS('02_KICH_BAN_NODES'!$B$5:$B$204,A66,'02_KICH_BAN_NODES'!$D$5:$D$204,"choice")=0,"ChoiceNodeId không tồn tại hoặc không phải choice",IF(COUNTIFS($A$5:$A$404,A66,$B$5:$B$404,B66)>1,"Trùng OptionOrder trong cùng choice",IF(OR(B66="",C66="",D66="",F66="",H66=""),"Thiếu trường bắt buộc",IF(OR(COUNTIF($A$5:$A$404,A66)<2,COUNTIF($A$5:$A$404,A66)>4),"Mỗi choice cần 2–4 option",IF(COUNTIFS('02_KICH_BAN_NODES'!$B$5:$B$204,A66,'02_KICH_BAN_NODES'!$E$5:$E$204,"Kiến thức")=1,IF(COUNTIFS($A$5:$A$404,A66,$D$5:$D$404,"Có")<>1,"Choice kiến thức cần đúng 1 đáp án đúng",""),IF(COUNTIFS('02_KICH_BAN_NODES'!$B$5:$B$204,A66,'02_KICH_BAN_NODES'!$E$5:$E$204,"Tương tác")=1,IF(COUNTIFS($A$5:$A$404,A66,$D$5:$D$404,"Có")<>0,"Choice tương tác không được đánh dấu đáp án đúng",""),"Choice chưa chọn loại")))))))
J67: =IF(A67="","",IF(K67="","HỢP LỆ","CẦN SỬA")) | K67: =IF(A67="","",IF(COUNTIFS('02_KICH_BAN_NODES'!$B$5:$B$204,A67,'02_KICH_BAN_NODES'!$D$5:$D$204,"choice")=0,"ChoiceNodeId không tồn tại hoặc không phải choice",IF(COUNTIFS($A$5:$A$404,A67,$B$5:$B$404,B67)>1,"Trùng OptionOrder trong cùng choice",IF(OR(B67="",C67="",D67="",F67="",H67=""),"Thiếu trường bắt buộc",IF(OR(COUNTIF($A$5:$A$404,A67)<2,COUNTIF($A$5:$A$404,A67)>4),"Mỗi choice cần 2–4 option",IF(COUNTIFS('02_KICH_BAN_NODES'!$B$5:$B$204,A67,'02_KICH_BAN_NODES'!$E$5:$E$204,"Kiến thức")=1,IF(COUNTIFS($A$5:$A$404,A67,$D$5:$D$404,"Có")<>1,"Choice kiến thức cần đúng 1 đáp án đúng",""),IF(COUNTIFS('02_KICH_BAN_NODES'!$B$5:$B$204,A67,'02_KICH_BAN_NODES'!$E$5:$E$204,"Tương tác")=1,IF(COUNTIFS($A$5:$A$404,A67,$D$5:$D$404,"Có")<>0,"Choice tương tác không được đánh dấu đáp án đúng",""),"Choice chưa chọn loại")))))))
J68: =IF(A68="","",IF(K68="","HỢP LỆ","CẦN SỬA")) | K68: =IF(A68="","",IF(COUNTIFS('02_KICH_BAN_NODES'!$B$5:$B$204,A68,'02_KICH_BAN_NODES'!$D$5:$D$204,"choice")=0,"ChoiceNodeId không tồn tại hoặc không phải choice",IF(COUNTIFS($A$5:$A$404,A68,$B$5:$B$404,B68)>1,"Trùng OptionOrder trong cùng choice",IF(OR(B68="",C68="",D68="",F68="",H68=""),"Thiếu trường bắt buộc",IF(OR(COUNTIF($A$5:$A$404,A68)<2,COUNTIF($A$5:$A$404,A68)>4),"Mỗi choice cần 2–4 option",IF(COUNTIFS('02_KICH_BAN_NODES'!$B$5:$B$204,A68,'02_KICH_BAN_NODES'!$E$5:$E$204,"Kiến thức")=1,IF(COUNTIFS($A$5:$A$404,A68,$D$5:$D$404,"Có")<>1,"Choice kiến thức cần đúng 1 đáp án đúng",""),IF(COUNTIFS('02_KICH_BAN_NODES'!$B$5:$B$204,A68,'02_KICH_BAN_NODES'!$E$5:$E$204,"Tương tác")=1,IF(COUNTIFS($A$5:$A$404,A68,$D$5:$D$404,"Có")<>0,"Choice tương tác không được đánh dấu đáp án đúng",""),"Choice chưa chọn loại")))))))
J69: =IF(A69="","",IF(K69="","HỢP LỆ","CẦN SỬA")) | K69: =IF(A69="","",IF(COUNTIFS('02_KICH_BAN_NODES'!$B$5:$B$204,A69,'02_KICH_BAN_NODES'!$D$5:$D$204,"choice")=0,"ChoiceNodeId không tồn tại hoặc không phải choice",IF(COUNTIFS($A$5:$A$404,A69,$B$5:$B$404,B69)>1,"Trùng OptionOrder trong cùng choice",IF(OR(B69="",C69="",D69="",F69="",H69=""),"Thiếu trường bắt buộc",IF(OR(COUNTIF($A$5:$A$404,A69)<2,COUNTIF($A$5:$A$404,A69)>4),"Mỗi choice cần 2–4 option",IF(COUNTIFS('02_KICH_BAN_NODES'!$B$5:$B$204,A69,'02_KICH_BAN_NODES'!$E$5:$E$204,"Kiến thức")=1,IF(COUNTIFS($A$5:$A$404,A69,$D$5:$D$404,"Có")<>1,"Choice kiến thức cần đúng 1 đáp án đúng",""),IF(COUNTIFS('02_KICH_BAN_NODES'!$B$5:$B$204,A69,'02_KICH_BAN_NODES'!$E$5:$E$204,"Tương tác")=1,IF(COUNTIFS($A$5:$A$404,A69,$D$5:$D$404,"Có")<>0,"Choice tương tác không được đánh dấu đáp án đúng",""),"Choice chưa chọn loại")))))))
J70: =IF(A70="","",IF(K70="","HỢP LỆ","CẦN SỬA")) | K70: =IF(A70="","",IF(COUNTIFS('02_KICH_BAN_NODES'!$B$5:$B$204,A70,'02_KICH_BAN_NODES'!$D$5:$D$204,"choice")=0,"ChoiceNodeId không tồn tại hoặc không phải choice",IF(COUNTIFS($A$5:$A$404,A70,$B$5:$B$404,B70)>1,"Trùng OptionOrder trong cùng choice",IF(OR(B70="",C70="",D70="",F70="",H70=""),"Thiếu trường bắt buộc",IF(OR(COUNTIF($A$5:$A$404,A70)<2,COUNTIF($A$5:$A$404,A70)>4),"Mỗi choice cần 2–4 option",IF(COUNTIFS('02_KICH_BAN_NODES'!$B$5:$B$204,A70,'02_KICH_BAN_NODES'!$E$5:$E$204,"Kiến thức")=1,IF(COUNTIFS($A$5:$A$404,A70,$D$5:$D$404,"Có")<>1,"Choice kiến thức cần đúng 1 đáp án đúng",""),IF(COUNTIFS('02_KICH_BAN_NODES'!$B$5:$B$204,A70,'02_KICH_BAN_NODES'!$E$5:$E$204,"Tương tác")=1,IF(COUNTIFS($A$5:$A$404,A70,$D$5:$D$404,"Có")<>0,"Choice tương tác không được đánh dấu đáp án đúng",""),"Choice chưa chọn loại")))))))
J71: =IF(A71="","",IF(K71="","HỢP LỆ","CẦN SỬA")) | K71: =IF(A71="","",IF(COUNTIFS('02_KICH_BAN_NODES'!$B$5:$B$204,A71,'02_KICH_BAN_NODES'!$D$5:$D$204,"choice")=0,"ChoiceNodeId không tồn tại hoặc không phải choice",IF(COUNTIFS($A$5:$A$404,A71,$B$5:$B$404,B71)>1,"Trùng OptionOrder trong cùng choice",IF(OR(B71="",C71="",D71="",F71="",H71=""),"Thiếu trường bắt buộc",IF(OR(COUNTIF($A$5:$A$404,A71)<2,COUNTIF($A$5:$A$404,A71)>4),"Mỗi choice cần 2–4 option",IF(COUNTIFS('02_KICH_BAN_NODES'!$B$5:$B$204,A71,'02_KICH_BAN_NODES'!$E$5:$E$204,"Kiến thức")=1,IF(COUNTIFS($A$5:$A$404,A71,$D$5:$D$404,"Có")<>1,"Choice kiến thức cần đúng 1 đáp án đúng",""),IF(COUNTIFS('02_KICH_BAN_NODES'!$B$5:$B$204,A71,'02_KICH_BAN_NODES'!$E$5:$E$204,"Tương tác")=1,IF(COUNTIFS($A$5:$A$404,A71,$D$5:$D$404,"Có")<>0,"Choice tương tác không được đánh dấu đáp án đúng",""),"Choice chưa chọn loại")))))))
J72: =IF(A72="","",IF(K72="","HỢP LỆ","CẦN SỬA")) | K72: =IF(A72="","",IF(COUNTIFS('02_KICH_BAN_NODES'!$B$5:$B$204,A72,'02_KICH_BAN_NODES'!$D$5:$D$204,"choice")=0,"ChoiceNodeId không tồn tại hoặc không phải choice",IF(COUNTIFS($A$5:$A$404,A72,$B$5:$B$404,B72)>1,"Trùng OptionOrder trong cùng choice",IF(OR(B72="",C72="",D72="",F72="",H72=""),"Thiếu trường bắt buộc",IF(OR(COUNTIF($A$5:$A$404,A72)<2,COUNTIF($A$5:$A$404,A72)>4),"Mỗi choice cần 2–4 option",IF(COUNTIFS('02_KICH_BAN_NODES'!$B$5:$B$204,A72,'02_KICH_BAN_NODES'!$E$5:$E$204,"Kiến thức")=1,IF(COUNTIFS($A$5:$A$404,A72,$D$5:$D$404,"Có")<>1,"Choice kiến thức cần đúng 1 đáp án đúng",""),IF(COUNTIFS('02_KICH_BAN_NODES'!$B$5:$B$204,A72,'02_KICH_BAN_NODES'!$E$5:$E$204,"Tương tác")=1,IF(COUNTIFS($A$5:$A$404,A72,$D$5:$D$404,"Có")<>0,"Choice tương tác không được đánh dấu đáp án đúng",""),"Choice chưa chọn loại")))))))
J73: =IF(A73="","",IF(K73="","HỢP LỆ","CẦN SỬA")) | K73: =IF(A73="","",IF(COUNTIFS('02_KICH_BAN_NODES'!$B$5:$B$204,A73,'02_KICH_BAN_NODES'!$D$5:$D$204,"choice")=0,"ChoiceNodeId không tồn tại hoặc không phải choice",IF(COUNTIFS($A$5:$A$404,A73,$B$5:$B$404,B73)>1,"Trùng OptionOrder trong cùng choice",IF(OR(B73="",C73="",D73="",F73="",H73=""),"Thiếu trường bắt buộc",IF(OR(COUNTIF($A$5:$A$404,A73)<2,COUNTIF($A$5:$A$404,A73)>4),"Mỗi choice cần 2–4 option",IF(COUNTIFS('02_KICH_BAN_NODES'!$B$5:$B$204,A73,'02_KICH_BAN_NODES'!$E$5:$E$204,"Kiến thức")=1,IF(COUNTIFS($A$5:$A$404,A73,$D$5:$D$404,"Có")<>1,"Choice kiến thức cần đúng 1 đáp án đúng",""),IF(COUNTIFS('02_KICH_BAN_NODES'!$B$5:$B$204,A73,'02_KICH_BAN_NODES'!$E$5:$E$204,"Tương tác")=1,IF(COUNTIFS($A$5:$A$404,A73,$D$5:$D$404,"Có")<>0,"Choice tương tác không được đánh dấu đáp án đúng",""),"Choice chưa chọn loại")))))))
J74: =IF(A74="","",IF(K74="","HỢP LỆ","CẦN SỬA")) | K74: =IF(A74="","",IF(COUNTIFS('02_KICH_BAN_NODES'!$B$5:$B$204,A74,'02_KICH_BAN_NODES'!$D$5:$D$204,"choice")=0,"ChoiceNodeId không tồn tại hoặc không phải choice",IF(COUNTIFS($A$5:$A$404,A74,$B$5:$B$404,B74)>1,"Trùng OptionOrder trong cùng choice",IF(OR(B74="",C74="",D74="",F74="",H74=""),"Thiếu trường bắt buộc",IF(OR(COUNTIF($A$5:$A$404,A74)<2,COUNTIF($A$5:$A$404,A74)>4),"Mỗi choice cần 2–4 option",IF(COUNTIFS('02_KICH_BAN_NODES'!$B$5:$B$204,A74,'02_KICH_BAN_NODES'!$E$5:$E$204,"Kiến thức")=1,IF(COUNTIFS($A$5:$A$404,A74,$D$5:$D$404,"Có")<>1,"Choice kiến thức cần đúng 1 đáp án đúng",""),IF(COUNTIFS('02_KICH_BAN_NODES'!$B$5:$B$204,A74,'02_KICH_BAN_NODES'!$E$5:$E$204,"Tương tác")=1,IF(COUNTIFS($A$5:$A$404,A74,$D$5:$D$404,"Có")<>0,"Choice tương tác không được đánh dấu đáp án đúng",""),"Choice chưa chọn loại")))))))
